<?xml version="1.0"?>
<robot xmlns:xacro="http://www.ros.org/wiki/xacro" >

    <xacro:include filename="inertial_macros.xacro"/>

    <material name="white">
        <color rgba="1 1 1 1" />
    </material>

    <material name="orange">
        <color rgba="1 0.3 0.1 1"/>
    </material>

    <material name="blue">
        <color rgba="0.2 0.2 1 1"/>
    </material>

    <material name="black">
        <color rgba="0 0 0 1"/>
    </material>

    <material name="gray">
        <color rgba="0.1 0.1 0.1 1"/>
    </material>

    <link name = "base_link"/>

    <joint name = "chassis_joint" type = "fixed">
        <parent link = "base_link"/>
        <child link = "chassis"/>
        <origin xyz = "0 0 0.1"/>
    </joint>

    <link name = "chassis">
        <origin xyz = "0 0 0"/>
        <visual>
            <origin xyz = "0 0.3 -0.05"/>
            <geometry>
                <box size = "0.2 0.6 0.1"/>
            </geometry>
            <material name = "blue"/>
        </visual>
    </link>

    <joint name="left_back_wheel_joint" type="continuous">
        <parent link="chassis"/>
        <child link="left_back_wheel"/>
        <origin xyz="-0.1 0 -0.05" rpy="0 -${pi/2} 0" />
        <axis xyz="0 0 1"/>
    </joint>

    <link name="left_back_wheel">
        <visual>
            <geometry>
                <cylinder radius="0.08" length="0.04"/>
            </geometry>
            <material name="blue"/>
        </visual> 
        <collision>
            <geometry> 
                <cylinder radius="0.08" length="0.04"/>
            </geometry> 
        </collision>
        <xacro:inertial_cylinder mass="0.1" length="0.04" radius="0.05">
            <origin xyz="0 0 0" rpy="0 0 0"/>
        </xacro:inertial_cylinder> 
    </link>
 
    <joint name="right_back_wheel_joint" type="continuous">
        <parent link="chassis"/> 
        <child link="right_back_wheel"/>
        <origin xyz="0.1 0 -0.05" rpy="0 ${pi/2} 0" />
        <axis xyz="0 0 -1"/>
    </joint>

    <link name="right_back_wheel">
        <visual>
            <geometry>
                <cylinder radius="0.08" length="0.04"/>
            </geometry>
            <material name="blue"/>
        </visual>
        <collision>
            <geometry>
                <cylinder radius="0.08" length="0.04"/>
            </geometry>
        </collision>
        <xacro:inertial_cylinder mass="0.1" length="0.04" radius="0.05">
            <origin xyz="0 0 0" rpy="0 0 0"/>
        </xacro:inertial_cylinder>
    </link>

    <joint name="left_front_wheel_joint" type="continuous">
        <parent link="chassis"/>
        <child link="left_front_wheel"/>
        <origin xyz="-0.1 0.6 -0.05" rpy="0 -${pi/2} 0" />
        <axis xyz="0 0 1"/>
    </joint>

    <link name="left_front_wheel">
        <visual>
            <geometry>
                <cylinder radius="0.08" length="0.04"/>
            </geometry>
            <material name="blue"/>
        </visual> 
        <collision>
            <geometry> 
                <cylinder radius="0.08" length="0.04"/>
            </geometry> 
        </collision>
        <xacro:inertial_cylinder mass="0.1" length="0.04" radius="0.05">
            <origin xyz="0 0 0" rpy="0 0 0"/>
        </xacro:inertial_cylinder> 
    </link>
 
    <joint name="right_front_wheel_joint" type="continuous">
        <parent link="chassis"/> 
        <child link="right_front_wheel"/>
        <origin xyz="0.1 0.6 -0.05" rpy="0 ${pi/2} 0" />
        <axis xyz="0 0 -1"/>
    </joint>

    <link name="right_front_wheel">
        <visual>
            <geometry>
                <cylinder radius="0.08" length="0.04"/>
            </geometry>
            <material name="blue"/>
        </visual>
        <collision>
            <geometry>
                <cylinder radius="0.08" length="0.04"/>
            </geometry>
        </collision>
        <xacro:inertial_cylinder mass="0.1" length="0.04" radius="0.05">
            <origin xyz="0 0 0" rpy="0 0 0"/>
        </xacro:inertial_cylinder>
    </link>

    <joint name = "crane_wheel_holder_joint" type ="revolute">
        <origin xyz = "0 0.3 0"/>
        <parent link = "chassis"/>
        <child link = "crane_wheel_holder"/>
        <limit lower = "-${pi}" upper = "${pi}" velocity = "0.5" effort = "1.0"/>
        <axis xyz = "0 0 1"/>
    </joint>

    <link name = "crane_wheel_holder">
        <visual>
            <origin xyz = "0 0 0.1"/>
            <geometry>
                <box size = "0.05 0.08 0.2"/>
            </geometry>
        </visual>
    </link>

    <joint name = "crane_wheel_joint" type = "revolute">
        <parent link = "crane_wheel_holder"/>
        <child link = "crane_wheel"/>
        <origin xyz = "0 0 0.2" rpy = "0 0 0"/>


        <axis xyz = "1 0 0"/>

        <limit lower = "-0.76" upper = "1.57" velocity = "5.0" effort = "1.0"/>
    </joint>

    <link name = "crane_wheel">
        <visual>
            <origin xyz = "0 0 0" rpy = "0 1.57 0"/>
            <geometry>
                <cylinder radius = "0.08" length = "0.005"/>
            </geometry>
            <material name = "green">
                <color rgba = "0 1 0 1"/>
            </material>
        </visual>
    </link>

    <joint name = "arm_joint" type = "fixed">
        <origin xyz = "0 0 0"/>
        <parent link = "crane_wheel"/>
        <child link = "arm"/>
    </joint>

    <link name = "arm">
        <origin xyz = "0 0 0"/>
        <visual>
            <origin xyz = "0 0.5 0" rpy = "1.57 0 0"/>
            <geometry>
                <cylinder radius = "0.004" length = "1.0"/>
            </geometry>
        </visual>
        <collision>
            <geometry>
                <cylinder radius="0.004" length="1.0"/>
            </geometry>
        </collision>
        <xacro:inertial_cylinder mass = "1.0" length = "1.0" radius = "0.004">
                <origin xyz = "0 0 0"/>
        </xacro:inertial_cylinder>
    </link>

    <joint name = "claw_base_joint" type = "revolute">
        <origin xyz = "0 1.0 0"/>
        <axis xyz = "1 0 0"/>
        <limit lower = "-0.7" upper = "0.7" velocity = "5.0" effort = "1.0"/>
        <parent link = "arm"/>
        <child link = "claw_base"/>
    </joint>

    <link name = "claw_base">
        <visual>
            <geometry>
                <box size = "0.2 0.04 0.04"/>
            </geometry>
            <material name = "blue"/>
        </visual>
    </link>

    <joint name = "claw_1_joint" type = "revolute">
        <origin xyz = "0.1 0 0"/>
        <parent link = "claw_base"/>
        <child link = "claw_1"/>

        <limit lower = "0" upper = "0.785" velocity = "1.0" effort = "0.3"/>
        <axis xyz = "0 0 1"/>
    </joint>


    <link name = "claw_1">
        <visual>
            <origin xyz = "0 0.05 0"/>
            <geometry>
                <box size = "0.02 0.1 0.02"/>
            </geometry>
        </visual>
    </link>

    <joint name = "claw_2_joint" type = "revolute">
        <origin xyz = "-0.1 0 0" rpy = "0 3.14 0"/>
        <parent link = "claw_base"/>
        <child link = "claw_2"/>

        <limit lower = "0" upper = "0.785" velocity = "1.0" effort = "0.3"/>
        <axis xyz = "0 0 1"/>
    </joint>

    <link name = "claw_2">
        <visual>
            <origin xyz = "0 0.05 0"/>
            <geometry>
                <box size = "0.02 0.1 0.02"/>
            </geometry>
        </visual>
    </link>

</robot>

<!--
    <link name="base_link">

    </link>

    <joint name="chassis_joint" type="fixed">
        <parent link="base_link"/>
        <child link="chassis"/>
        <origin xyz="-0.1 0 0"/>
    </joint>

    <link name="chassis">
        <visual>
            <origin xyz="0.15 0 0.075"/>
            <geometry>
                <box size="0.3 0.3 0.15"/>
            </geometry>
            <material name="white"/>
        </visual>
        <collision>
            <origin xyz="0.15 0 0.075"/>
            <geometry>
                <box size="0.3 0.3 0.15"/>
            </geometry>
        </collision>
        <xacro:inertial_box mass="0.5" x="0.3" y="0.3" z="0.15">
            <origin xyz="0.15 0 0.075" rpy="0 0 0"/>
        </xacro:inertial_box>
    </link>
    
    <joint name = "crane_base_joint" type = "fixed">
        <parent link = "chassis"/>
        <child link = "crane_base"/>
        <origin xyz="0 0 0"/>
    </joint>

    <link name = "crane_base">
        <visual>
            <origin xyz = "0 0 0.2"/>
            <geometry>
                <box size = "0.1 0.05 0.2"/>
            </geometry>
            <material name = "gray"/>
        </visual>
        <xacro:inertial_box mass = "0.2" x = "0.2" y = "0.8"  z ="1.5">
            <origin xyz = "0 0 0.8" rpy = "0 0 0"/>
        </xacro:inertial_box>
    </link>

    <joint name = "crane_joint" type = "revolute">
        <parent link = "crane_base"/>
        <child link = "crane"/>
        <origin xyz = "0 0 0.3" rpy = "0.0 1.57 0.0"/>
        <limit lower = "-1.57" upper = "1.57" effort = "1.0" velocity = "5.0"/>
        <axis xyz = "0 1 0"/>
    </joint>

    <link name="crane">
        <visual>
            <geometry>
                <cylinder radius="0.04" length="0.4"/>
            </geometry>
            <material name="LightGrey">
                <color rgba="0.7 0.7 0.7 1.0"/>
            </material>
            <origin xyz = "0.0 0.0 0.25"/>
        </visual>
        <collision>
            <geometry>
                <cylinder radius="0.5" length="1.0"/>
            </geometry>
        </collision>
        <xacro:inertial_cylinder mass = "1.0" length = "1.0" radius = "0.04">
                <origin xyz = "0 0 0"/>
        </xacro:inertial_cylinder>
    </link>

    <joint name="left_wheel_joint" type="continuous">
        <parent link="base_link"/>
        <child link="left_wheel"/>
        <origin xyz="0 0.175 0" rpy="-${pi/2} 0 0" />
        <axis xyz="0 0 1"/>
    </joint>

    <link name="left_wheel">
        <visual>
            <geometry>
                <cylinder radius="0.05" length="0.04"/>
            </geometry>
            <material name="blue"/>
        </visual> 
        <collision>
            <geometry> 
                <cylinder radius="0.05" length="0.04"/>
            </geometry> 
        </collision>
        <xacro:inertial_cylinder mass="0.1" l ength="0.04" radius="0.05">
            <origin xyz="0 0 0" rpy="0 0 0"/>
        </xacro:inertial_cylinder> 
    </link>
 
    <joint name="right_wheel_joint" type="continuous">
        <parent link="base_link"/> 
        <child link="right_wheel"/>
        <origin xyz="0 -0.175 0" rpy="${pi/2}  0 0" />
        <axis xyz="0 0 -1"/>
    </joint>

    <link name="right_wheel">
        <visual>
            <geometry>
                <cylinder radius="0.05" length="0.04"/>
            </geometry>
            <material name="blue"/>
        </visual>
        <collision>
            <geometry>
                <cylinder radius="0.05" length="0.04"/>
            </geometry>
        </collision>
        <xacro:inertial_cylinder mass="0.1" length="0.04" radius="0.05">
            <origin xyz="0 0 0" rpy="0 0 0"/>
        </xacro:inertial_cylinder>
    </link>
-->